<?xml version="1.0" ?>
<!-- =================================================================================== -->
<!-- |    This document was autogenerated by xacro from robot.urdf.xacro               | -->
<!-- |    EDITING THIS FILE BY HAND IS NOT RECOMMENDED                                 | -->
<!-- =================================================================================== -->
<robot name="robot">
  
  <material name="white">
    <color rgba="1 1 1 1"/>
  </material>

  <material name="black">
    <color rgba="0.3 0.3 0.3 1"/>
  </material>
  
  <material name="blue">
    <color rgba="0.1 0.2 0.6 1"/>
  </material>
  
  <material name="red">
    <color rgba="0.8 0.1 0.1 1"/>
  </material>
  
  <material name="green">
    <color rgba="0.1 0.8 0.2 1"/>
  </material>
  
  <link name="world"/>
  
  <link name="base_link">
    <inertial>
      <origin rpy="0 0 0" xyz="-1.0022E-17 0.031146 1.6931E-17"/>
      <mass value="1.7941"/>
      <inertia ixx="0.0048349" ixy="3.0467E-20" ixz="1.8103E-18" iyy="0.0083635" iyz="8.3712E-19" izz="0.0048349"/>
    </inertial>
    <visual>
      <origin rpy="0 0 0" xyz="0 0 0"/>
      <geometry>
        <mesh filename="meshes/base_link.stl"/>
      </geometry>
      <material name="black">
      </material>
    </visual>
    <collision>
      <origin rpy="0 0 0" xyz="0 0 0"/>
      <geometry>
        <mesh filename="meshes/base_link.stl"/>
      </geometry>
    </collision>
  </link>
  
  <link name="link1">
    <inertial>
      <origin rpy="0 0 0" xyz="-0.00033867 0.0 0.04069188"/>
      <mass value="0.26598862"/>
      <inertia ixx="0.00069223" ixy="0.0" ixz="-0.00000598" iyy="0.00112777" iyz="0.0" izz="0.00066577"/>
    </inertial>
    <visual>
      <origin rpy="0 0 0" xyz="0 0 0"/>
      <geometry>
        <mesh filename="meshes/link_1.stl"/>
      </geometry>
      <material name="blue">
      </material>
    </visual>
    <collision>
      <origin rpy="0 0 0" xyz="0 0 0"/>
      <geometry>
        <mesh filename="meshes/link_1.stl"/>
      </geometry>
    </collision>
  </link>
  
  <link name="link2">
    <inertial>
      <origin rpy="0 0 0" xyz="0.00047806 0.0 0.12861482"/>
      <mass value="0.29648615"/>
      <inertia ixx="0.00610192" ixy="0.0" ixz="0.00001654" iyy="0.00662316" iyz="0.00000002" izz="0.00058255"/>
    </inertial>
    <visual>
      <origin rpy="0 0 0" xyz="0 0 0"/>
      <geometry>
        <mesh filename="meshes/link_2.stl"/>
      </geometry>
      <material name="black">
      </material>
    </visual>
    <collision>
      <origin rpy="0 0 0" xyz="0 0 0"/>
      <geometry>
        <mesh filename="meshes/link_2.stl"/>
      </geometry>
    </collision>
  </link>

  <link name="link3">
    <inertial>
      <origin rpy="0 0 0" xyz="-0.00053036 0.0 0.10618762"/>
      <mass value="0.18197777"/>
      <inertia ixx="0.00288076" ixy="0.0" ixz="-0.00000804" iyy="0.00301111" iyz="0.0" izz="0.00016902"/>
    </inertial>
    <visual>
      <origin rpy="0 0 0" xyz="0 0 0"/>
      <geometry>
        <mesh filename="meshes/link_3.stl"/>
      </geometry>
      <material name="black">
      </material>
    </visual>
    <collision>
      <origin rpy="0 0 0" xyz="0 0 0"/>
      <geometry>
        <mesh filename="meshes/link_3.stl"/>
      </geometry>
    </collision>
  </link>

  <link name="link4">
    <inertial>
      <origin rpy="0 0 0" xyz="-0.00023697 0.00957601 0.05302509"/>
      <mass value="0.10881011"/>
      <inertia ixx="0.00039796" ixy="0.0" ixz="0.0" iyy="0.00038409" iyz="0.00006328" izz="0.00004420"/>
    </inertial>
    <visual>
      <origin rpy="0 0 0" xyz="0 0 0"/>
      <geometry>
        <mesh filename="meshes/link_4.stl"/>
      </geometry>
      <material name="black">
      </material>
    </visual>
    <collision>
      <origin rpy="0 0 0" xyz="0 0 0"/>
      <geometry>
        <mesh filename="meshes/link_4.stl"/>
      </geometry>
    </collision>
  </link>

  <link name="link5">
    <inertial>
      <origin rpy="0 0 0" xyz="-0.00039819 -0.00306049 0.04570833"/>
      <mass value="0.11311685"/>
      <inertia ixx="0.00034785" ixy="0.0" ixz="-0.00000314" iyy="0.00035044" iyz="-0.00000105" izz="0.00003925"/>
    </inertial>
    <visual>
      <origin rpy="0 0 0" xyz="0 0 0"/>
      <geometry>
        <mesh filename="meshes/link_5.stl"/>
      </geometry>
      <material name="red">
      </material>
    </visual>
    <collision>
      <origin rpy="0 0 0" xyz="0 0 0"/>
      <geometry>
        <mesh filename="meshes/link_5.stl"/>
      </geometry>
    </collision>
  </link>
  
  <joint name="world_base" type="fixed">
    <parent link="world"/>
    <child link="base_link"/>
    <origin rpy="0 0 0" xyz="0 0 0"/>
  </joint>
  
  <joint name="joint1" type="revolute">
    <origin rpy="0 0 0" xyz="0 0 0.0592"/>
    <parent link="base_link"/>
    <child link="link1"/>
    <axis xyz="0 0 1"/>
    <limit effort="4.5" lower="-2.09" upper="2.09" velocity="5.82"/>
  </joint>
  
  <joint name="joint2" type="revolute">
    <origin rpy="0 0 0" xyz="0 0 0.0678"/>
    <parent link="link1"/>
    <child link="link2"/>
    <axis xyz="1 0 0"/>
    <limit effort="9.0" lower="-1.57" upper="1.57" velocity="5.82"/>
  </joint>
  
  <joint name="joint3" type="revolute">
    <origin rpy="0 0 0" xyz="0 0 0.185"/>
    <parent link="link2"/>
    <child link="link3"/>
    <axis xyz="1 0 0"/>
    <limit effort="9.0" lower="-1.57" upper="1.57" velocity="5.82"/>
  </joint>
  
  <joint name="joint4" type="revolute">
    <origin rpy="0 0 0" xyz="0 0 0.18"/>
    <parent link="link3"/>
    <child link="link4"/>
    <axis xyz="1 0 0"/>
    <limit effort="4.5" lower="-1.57" upper="1.57" velocity="5.82"/>
  </joint>
  
  <joint name="joint5" type="revolute">
    <origin rpy="0 0 0" xyz="0.0 0.0 0.065"/>
    <parent link="link4"/>
    <child link="link5"/>
    <axis xyz="0 0 1"/>
    <limit effort="4.5" lower="-1.57" upper="1.57" velocity="5.82"/>
  </joint>
  
  <joint name="joint6" type="revolute">
    <origin rpy="0 0 0" xyz="0 0 0.07"/>
    <parent link="link5"/>
    <child link="gripper_base_link"/>
    <axis xyz="1 0 0"/>
    <limit effort="4.5" lower="-1.57" upper="1.57" velocity="5.82"/>
  </joint>
  
  <link name="gripper_base_link">
    <inertial> 
      <origin rpy="0 0 0" xyz="-0.00010299 -0.02688450 0.06603903"/>
      <mass value="0.26325356"/>
      <inertia ixx="0.00176368" ixy="-0.00000086" ixz="0.00000594" iyy="0.00146563" iyz="-0.00049322" izz="0.00066230"/>
    </inertial> 
    <visual>
      <origin rpy="0 0 0" xyz="0 0 0"/>
      <geometry>
        <mesh filename="meshes/gripper_base_link.stl"/>
      </geometry>
      <material name="white">
      </material>
    </visual>
    <collision>
      <origin rpy="0 0 0" xyz="0 0 0"/>
      <geometry>
        <mesh filename="meshes/gripper_base_link.stl"/>
      </geometry>
    </collision>
  </link>
  
  <link name="gripper_left_finger_link">
    <inertial>
      <origin rpy="0 0 0" xyz="-0.04936121 -0.00165819 0.00790974"/>
      <mass value="0.01666"/>
      <inertia ixx="0.00000859" ixy="0.00000172" ixz="-0.00000330" iyy="0.00005127" iyz="0.00000067" izz="0.00004602"/>
    </inertial>
    <visual>
      <origin rpy="0 0 0" xyz="0 0 0"/>
      <geometry>
        <mesh filename="meshes/gripper_link_left.stl"/>
      </geometry>
      <material name="red">
      </material>
    </visual>
    <collision>
      <origin rpy="0 0 0" xyz="0 0 0"/>
      <geometry>
        <mesh filename="meshes/gripper_link_left.stl"/>
      </geometry>
    </collision>
  </link>
  
  <link name="gripper_right_finger_link">
    <inertial>
      <origin rpy="0 0 0" xyz="0.04936121 -0.00165819 0.00790974"/>
      <mass value="0.01666"/>
      <inertia ixx="0.00000859" ixy="-0.00000172" ixz="0.00000330" iyy="0.00005127" iyz="0.00000067" izz="0.00004602"/>
    </inertial>
    <visual>
      <origin rpy="0 0 0" xyz="0 0 0"/>
      <geometry>
        <mesh filename="meshes/gripper_link_right.stl"/>
      </geometry>
      <material name="red">
      </material>
    </visual>
    <collision>
      <origin rpy="0 0 0" xyz="0 0 0"/>
      <geometry>
        <mesh filename="meshes/gripper_link_right.stl"/>
      </geometry>
    </collision>
  </link>
  
  <link name="camera">
    <inertial>
      <origin rpy="0 0 0" xyz="0.0 0.0 -0.0005"/>
      <mass value="0.072"/>
      <inertia ixx="0.00000047" ixy="0.0" ixz="0.0" iyy="0.00000047" iyz="0.0" izz="0.00000090"/>
    </inertial>
    <visual>
      <origin rpy="0 0 0" xyz="0 0 0"/>
      <geometry>
        <mesh filename="meshes/camera.stl"/>
      </geometry>
      <material name="black">
      </material>
    </visual>
    <collision>
      <origin rpy="0 0 0" xyz="0 0 0"/>
      <geometry>
        <mesh filename="meshes/camera.stl"/>
      </geometry>
    </collision>
  </link>
  
  <link name="ee_ref_link">
    <inertial>
      <origin rpy="0 0 0" xyz="0 0 0"/>
      <mass value="0.0001"/>
      <inertia ixx="0.000000001" ixy="0" ixz="0" iyy="0.000000001" iyz="0" izz="0.000000001"/>
    </inertial>
    <visual>
      <geometry>
        <sphere radius="0.01"/>
      </geometry>
      <material name="black"/>
    </visual>
  </link>

  <!-- X axis (red) -->
  <link name="ee_axis_x">
    <inertial>
      <origin rpy="0 0 0" xyz="0 0 0"/>
      <mass value="0.00001"/>
      <inertia ixx="0.000000001" ixy="0" ixz="0" iyy="0.000000001" iyz="0" izz="0.000000001"/>
    </inertial>
    <visual>
      <origin rpy="0 0 0" xyz="0 0 0"/>
      <geometry>
        <mesh filename="meshes/axis_x.stl"/>
      </geometry>
      <material name="red">
      </material>
    </visual>
  </link>

  <!-- Y axis (green) -->
  <link name="ee_axis_y">
    <inertial>
      <origin rpy="0 0 0" xyz="0 0 0"/>
      <mass value="0.00001"/>
      <inertia ixx="0.000000001" ixy="0" ixz="0" iyy="0.000000001" iyz="0" izz="0.000000001"/>
    </inertial>
    <visual>
      <origin rpy="0 0 0" xyz="0 0 0"/>
      <geometry>
        <mesh filename="meshes/axis_y.stl"/>
      </geometry>
      <material name="green">
      </material>
    </visual>
  </link>

  <!-- Z axis (blue) -->
  <link name="ee_axis_z">
    <inertial>
      <origin rpy="0 0 0" xyz="0 0 0"/>
      <mass value="0.00001"/>
      <inertia ixx="0.000000001" ixy="0" ixz="0" iyy="0.000000001" iyz="0" izz="0.000000001"/>
    </inertial>
    <visual>
      <origin rpy="0 0 0" xyz="0 0 0"/>
      <geometry>
        <mesh filename="meshes/axis_z.stl"/>
      </geometry>
      <material name="blue">
      </material>
    </visual>
  </link>
  
  <joint name="gripper_left_finger_joint" type="prismatic">
    <origin rpy="0 0 0" xyz="0.0 -0.00758 0.111"/>
    <parent link="gripper_base_link"/>
    <child link="gripper_left_finger_link"/>
    <axis xyz="1 0 0"/>
    <limit effort="4.5" lower="0.0" upper="0.039" velocity="1"/>
  </joint>

  <joint name="gripper_right_finger_joint" type="prismatic">
    <origin rpy="0 0 0" xyz="0.0 -0.00758 0.111"/>
    <parent link="gripper_base_link"/>
    <child link="gripper_right_finger_link"/>
    <axis xyz="1 0 0"/>
    <mimic joint="gripper_left_finger_joint" multiplier="-1.0"/>
    <limit effort="4.5" lower="-0.039" upper="0.0" velocity="1"/>
  </joint>

  <joint name="camera" type="fixed">
    <origin rpy="0 0 0" xyz="0 -0.07367 0.07055"/>
    <parent link="gripper_base_link"/>
    <child link="camera"/>
  </joint>

  <joint name="ee_ref_joint" type="fixed">
    <parent link="gripper_base_link"/>
    <child link="ee_ref_link"/>
    <origin rpy="0 0 0" xyz="0 -0.00758 0.155"/>
  </joint>

  <joint name="ee_axis_x_joint" type="fixed">
    <parent link="ee_ref_link"/>
    <child link="ee_axis_x"/>
    <origin rpy="0 0 0" xyz="0 0 0"/>
  </joint>

  <joint name="ee_axis_y_joint" type="fixed">
    <parent link="ee_ref_link"/>
    <child link="ee_axis_y"/>
    <origin rpy="0 0 0" xyz="0 0 0"/>
  </joint>

  <joint name="ee_axis_z_joint" type="fixed">
    <parent link="ee_ref_link"/>
    <child link="ee_axis_z"/>
    <origin rpy="0 0 0" xyz="0 0 0"/>
  </joint>

</robot>
